#VRML_SIM R2020b utf8
WorldInfo {
  coordinateSystem "NUE"
}
Viewpoint {
  orientation -0.999003516253968 -0.040592853787913045 -0.018552485913242597 1.1166394473339505
  position 0.0742259028429686 2.0355955102147854 0.9385578508106048
}
TexturedBackground {
}
TexturedBackgroundLight {
}
Floor {
  size 2 2
}
Solid {
  translation -1 0.05 0
  children [
    DEF WALL Shape {
      appearance PBRAppearance {
        baseColor 0.0261692 0 0.998199
        metalness 0
      }
      geometry Box {
        size 0.01 0.1 2
      }
    }
  ]
  name "Wall 1"
  boundingObject USE WALL
}
Solid {
  translation 0 0.05 -1
  rotation 0 1 0 1.57
  children [
    USE WALL
  ]
  name "Wall 2"
  boundingObject USE WALL
}
Solid {
  translation 1 0.05 0
  children [
    USE WALL
  ]
  name "Wall 3"
  boundingObject USE WALL
}
Solid {
  translation 0 0.05 1
  rotation 0 1 0 1.57
  children [
    USE WALL
  ]
  name "Wall 4"
  boundingObject USE WALL
}
Robot {
  translation 1.828718177358206e-10 0.0395245131803798 1.3780494224902018e-08
  rotation 0.9999999998847576 -1.505664315668199e-05 -1.9447234051883436e-06 0.008004818123457661
  children [
    HingeJoint {
      jointParameters HingeJointParameters {
        position -7.615999262983206
        anchor 0.06 0 0.05
      }
      device [
        RotationalMotor {
          name "Wheel 1"
        }
      ]
      endPoint Solid {
        translation 0.05999999934251677 -3.646626193472783e-06 0.05000144893932342
        rotation -0.5270048283965416 0.527006764264937 0.6667306662106769 1.9655022252658476
        children [
          DEF WHEELS Shape {
            appearance PBRAppearance {
              baseColor 0.154971 1 0.0374304
              metalness 0
            }
            geometry Cylinder {
              height 0.02
              radius 0.04
            }
          }
        ]
        name "Wheel 1"
        boundingObject USE WHEELS
        physics DEF WHEEL_PH Physics {
        }
      }
    }
    DEF CHASSIS Shape {
      appearance PBRAppearance {
        baseColor 0.986282 0.0463111 0.121553
        metalness 0
      }
      geometry Box {
        size 0.1 0.05 0.2
      }
    }
    HingeJoint {
      jointParameters HingeJointParameters {
        position -7.615999834883571
        anchor 0.06 0 -0.05
      }
      device [
        RotationalMotor {
          name "Wheel 2"
        }
      ]
      endPoint Solid {
        translation 0.06000000065788258 -3.6466319922801447e-06 -0.04999855107528265
        rotation -0.5270049660157433 0.5270069018898569 0.6667304486486274 1.9655025264263182
        children [
          USE WHEELS
        ]
        boundingObject USE WHEELS
        physics USE WHEEL_PH
      }
    }
    HingeJoint {
      jointParameters HingeJointParameters {
        position -7.615999263891412
        anchor -0.06 0 0.05
      }
      device [
        RotationalMotor {
          name "Wheel 3"
        }
      ]
      endPoint Solid {
        translation -0.06000000065748304 -3.6461562994477847e-06 0.05000145044468607
        rotation -0.5270048286161649 0.5270067644845603 0.6667306658634817 1.9655022257465526
        children [
          USE WHEELS
        ]
        name "solid(1)"
        boundingObject USE WHEELS
        physics USE WHEEL_PH
      }
    }
    HingeJoint {
      jointParameters HingeJointParameters {
        position -7.61599983519247
        anchor -0.06 0 -0.05
      }
      device [
        RotationalMotor {
          name "Wheel 4"
        }
      ]
      endPoint Solid {
        translation -0.059999999342117236 -3.6461620983997926e-06 -0.049998549569922425
        rotation -0.5270049660910675 0.5270069019651836 0.6667304485295479 1.965502526591184
        children [
          USE WHEELS
        ]
        name "solid(2)"
        boundingObject USE WHEELS
        physics USE WHEEL_PH
      }
    }
    DistanceSensor {
      translation 0 0 0.1
      rotation 0 1 0 -1.57
      children [
        Solid {
          children [
            DEF SENSOR Shape {
              appearance PBRAppearance {
                baseColor 0.0684367 0 0.998215
                metalness 0
              }
              geometry Box {
                size 0.01 0.01 0.01
              }
            }
          ]
          boundingObject USE SENSOR
        }
      ]
      name "sensor 1"
      physics Physics {
      }
      lookupTable [
        0 1023 0
        0.02 1023 0
        0.3 0 0
      ]
      type "sonar"
      numberOfRays 2
      aperture 0.75
    }
  ]
  name "4 Wheel Robot"
  boundingObject USE CHASSIS
  physics Physics {
  }
  controller "Obstancle_Avoidance"
  linearVelocity 1.2876875180892015e-16 -5.161382432561368e-14 3.793485748173878e-13
  angularVelocity 1.040266503935141e-12 4.05894265711302e-15 -5.09640403313716e-16
}
Solid {
  translation 3.9071782219286475e-19 0.09686079999999998 0.48
  rotation -0.15794002706376645 0.2775483210019586 0.9476401623823733 2.6992881372881077e-17
  children [
    DEF BOX Shape {
      appearance PBRAppearance {
        baseColor 0.99968 0.959503 0.041062
        metalness 0
      }
      geometry Box {
        size 0.2 0.2 0.2
      }
    }
  ]
  boundingObject USE BOX
  physics Physics {
  }
  linearVelocity 1.8710306367402157e-17 3.907057168519688e-17 2.136767583628794e-17
  angularVelocity 3.996802888650559e-16 -9.72382896606904e-19 -1.3322676295501792e-16
}
