#VRML_SIM R2020b utf8
WorldInfo {
  coordinateSystem "NUE"
}
Viewpoint {
  orientation -0.9988606729594213 -0.044161890735192375 -0.018085447789449094 1.0367246658928087
  position 0.04636331680189769 2.579319658815553 1.4615866461105824
}
TexturedBackground {
}
TexturedBackgroundLight {
}
Floor {
  size 2 2
}
Solid {
  translation -1 0.05 0
  children [
    DEF WALL Shape {
      appearance PBRAppearance {
        baseColor 0.0261692 0 0.998199
        metalness 0
      }
      geometry Box {
        size 0.01 0.1 2
      }
    }
  ]
  name "Wall 1"
  boundingObject USE WALL
}
Solid {
  translation 0 0.05 -1
  rotation 0 1 0 1.57
  children [
    USE WALL
  ]
  name "Wall 2"
  boundingObject USE WALL
}
Solid {
  translation 1 0.05 0
  children [
    USE WALL
  ]
  name "Wall 3"
  boundingObject USE WALL
}
Solid {
  translation 0 0.05 1
  rotation 0 1 0 1.57
  children [
    USE WALL
  ]
  name "Wall 4"
  boundingObject USE WALL
}
Robot {
  translation 0 0.039721 0
  rotation 5.888689878406685e-05 0.6590019810169327 0.7521412005388958 6.751917834410859e-08
  children [
    HingeJoint {
      jointParameters HingeJointParameters {
        position -4.09599996139235
        anchor 0.06 0 0.05
      }
      device [
        RotationalMotor {
          name "Wheel 1"
        }
      ]
      endPoint Solid {
        translation 0.05999999934251677 3.9239402586654926e-06 0.05000000077737628
        rotation 0.6636329058971091 -0.6636353436564075 0.3452238358813028 2.476767790671629
        children [
          DEF WHEELS Shape {
            appearance PBRAppearance {
              baseColor 0.154971 1 0.0374304
              metalness 0
            }
            geometry Cylinder {
              height 0.02
              radius 0.04
            }
          }
        ]
        name "Wheel 1"
        boundingObject USE WHEELS
        physics DEF WHEEL_PH Physics {
        }
      }
    }
    DEF CHASSIS Shape {
      appearance PBRAppearance {
        baseColor 0.986282 0.0463111 0.121553
        metalness 0
      }
      geometry Box {
        size 0.1 0.05 0.2
      }
    }
    HingeJoint {
      jointParameters HingeJointParameters {
        position -4.096000026056581
        anchor 0.06 0 -0.05
      }
      device [
        RotationalMotor {
          name "Wheel 2"
        }
      ]
      endPoint Solid {
        translation 0.06000000065788258 3.923940250762092e-06 -0.049999999204918294
        rotation 0.6636328997031784 -0.6636353374254278 0.3452238597660796 2.476767748009674
        children [
          USE WHEELS
        ]
        boundingObject USE WHEELS
        physics USE WHEEL_PH
      }
    }
    HingeJoint {
      jointParameters HingeJointParameters {
        position -4.095999961092049
        anchor -0.06 0 0.05
      }
      device [
        RotationalMotor {
          name "Wheel 3"
        }
      ]
      endPoint Solid {
        translation -0.06000000065748304 3.9240597491871365e-06 0.049999999204918266
        rotation 0.6636329059257356 -0.6636353436850339 0.3452238357712441 2.476767790868307
        children [
          USE WHEELS
        ]
        name "solid(1)"
        boundingObject USE WHEELS
        physics USE WHEEL_PH
      }
    }
    HingeJoint {
      jointParameters HingeJointParameters {
        position -4.096000025756281
        anchor -0.06 0 -0.05
      }
      device [
        RotationalMotor {
          name "Wheel 4"
        }
      ]
      endPoint Solid {
        translation -0.059999999342117236 3.924059741318431e-06 -0.05000000077737629
        rotation 0.6636328997318046 -0.6636353374540539 0.3452238596560219 2.4767677482063495
        children [
          USE WHEELS
        ]
        name "solid(2)"
        boundingObject USE WHEELS
        physics USE WHEEL_PH
      }
    }
    DistanceSensor {
      translation 0 0 0.1
      rotation 0 1 0 -1.57
      children [
        Solid {
          children [
            DEF SENSOR Shape {
              appearance PBRAppearance {
                baseColor 0.0684367 0 0.998215
                metalness 0
              }
              geometry Box {
                size 0.01 0.01 0.01
              }
            }
          ]
          boundingObject USE SENSOR
        }
      ]
      physics Physics {
      }
      lookupTable [
        0 1023 0
        0.02 1023 0
        0.3 0 0
      ]
      type "sonar"
      numberOfRays 2
      aperture 0.75
    }
  ]
  name "4 Wheel Robot"
  boundingObject USE CHASSIS
  physics Physics {
  }
  controller "Basic_Movements"
}
