#VRML_SIM R2020b utf8
WorldInfo {
  coordinateSystem "NUE"
}
Viewpoint {
  orientation -0.514107315821313 -0.8179780490699005 -0.2580805669917913 1.124034421252597
  position -1.769788061496748 1.3368593390537373 1.6392754682946544
}
TexturedBackground {
}
TexturedBackgroundLight {
}
Floor {
  size 2 2
}
Solid {
  translation -1 0.05 0
  children [
    DEF WALL Shape {
      appearance PBRAppearance {
        baseColor 0.0261692 0 0.998199
        metalness 0
      }
      geometry Box {
        size 0.01 0.1 2
      }
    }
  ]
  name "Wall 1"
  boundingObject USE WALL
}
Solid {
  translation 0 0.05 -1
  rotation 0 1 0 1.57
  children [
    USE WALL
  ]
  name "Wall 2"
  boundingObject USE WALL
}
Solid {
  translation 1 0.05 0
  children [
    USE WALL
  ]
  name "Wall 3"
  boundingObject USE WALL
}
Solid {
  translation 0 0.05 1
  rotation 0 1 0 1.57
  children [
    USE WALL
  ]
  name "Wall 4"
  boundingObject USE WALL
}
Robot {
  translation -6.493355191713449e-10 0.03972097929888863 4.547984591076004e-14
  rotation 6.506826339848278e-08 -9.747060581574087e-08 0.9999999999999931 -9.034452408755613e-08
  children [
    HingeJoint {
      jointParameters HingeJointParameters {
        position 1.288138933262702e-11
        anchor 0.06 0 0.05
      }
      device [
        RotationalMotor {
          name "Wheel 1"
        }
      ]
      endPoint Solid {
        translation 0.06 0 0.05
        rotation 2.578022695963951e-11 -2.578032165587466e-11 1 1.5707999999999998
        children [
          DEF WHEELS Shape {
            appearance PBRAppearance {
              baseColor 0.154971 1 0.0374304
              metalness 0
            }
            geometry Cylinder {
              height 0.02
              radius 0.04
            }
          }
        ]
        name "Wheel 1"
        boundingObject USE WHEELS
        physics DEF WHEEL_PH Physics {
        }
      }
    }
    DEF CHASSIS Shape {
      appearance PBRAppearance {
        baseColor 0.986282 0.0463111 0.121553
        metalness 0
      }
      geometry Box {
        size 0.1 0.05 0.2
      }
    }
    HingeJoint {
      jointParameters HingeJointParameters {
        position 1.2882761107923076e-11
        anchor 0.06 0 -0.05
      }
      device [
        RotationalMotor {
          name "Wheel 2"
        }
      ]
      endPoint Solid {
        translation 0.06 0 -0.05
        rotation 2.578312615333975e-11 -2.578322086022424e-11 1 1.5707999999999998
        children [
          USE WHEELS
        ]
        boundingObject USE WHEELS
        physics USE WHEEL_PH
      }
    }
    HingeJoint {
      jointParameters HingeJointParameters {
        position 1.298830425922877e-11
        anchor -0.06 0 0.05
      }
      device [
        RotationalMotor {
          name "Wheel 3"
        }
      ]
      endPoint Solid {
        translation -0.06 0 0.05
        rotation 2.5941119584397606e-11 -2.5941214871625443e-11 1 1.5707999999999998
        children [
          USE WHEELS
        ]
        name "solid(1)"
        boundingObject USE WHEELS
        physics USE WHEEL_PH
      }
    }
    HingeJoint {
      jointParameters HingeJointParameters {
        position 1.298921321703823e-11
        anchor -0.06 0 -0.05
      }
      device [
        RotationalMotor {
          name "Wheel 4"
        }
      ]
      endPoint Solid {
        translation -0.06 0 -0.05
        rotation 2.5943104089316134e-11 -2.5943199383833474e-11 1 1.5707999999999998
        children [
          USE WHEELS
        ]
        name "solid(2)"
        boundingObject USE WHEELS
        physics USE WHEEL_PH
      }
    }
  ]
  name "4 Wheel Robot"
  boundingObject USE CHASSIS
  physics Physics {
  }
  controller "Basic_Movements"
  linearVelocity -2.456395712208895e-13 -3.1934064281813328e-12 2.5612673095319553e-12
  angularVelocity -3.977367486186978e-13 1.9563935768323722e-13 6.133120677986873e-12
}
