#VRML_SIM R2020b utf8
WorldInfo {
  coordinateSystem "NUE"
}
Viewpoint {
  orientation -0.514107315821313 -0.8179780490699005 -0.2580805669917913 1.124034421252597
  position -1.769788061496748 1.3368593390537373 1.6392754682946544
}
TexturedBackground {
}
TexturedBackgroundLight {
}
Floor {
  size 2 2
}
Solid {
  translation -1 0.05 0
  children [
    DEF WALL Shape {
      appearance PBRAppearance {
        baseColor 0.0261692 0 0.998199
        metalness 0
      }
      geometry Box {
        size 0.01 0.1 2
      }
    }
  ]
  name "Wall 1"
  boundingObject USE WALL
}
Solid {
  translation 0 0.05 -1
  rotation 0 1 0 1.57
  children [
    USE WALL
  ]
  name "Wall 2"
  boundingObject USE WALL
}
Solid {
  translation 1 0.05 0
  children [
    USE WALL
  ]
  name "Wall 3"
  boundingObject USE WALL
}
Solid {
  translation 0 0.05 1
  rotation 0 1 0 1.57
  children [
    USE WALL
  ]
  name "Wall 4"
  boundingObject USE WALL
}
Robot {
  translation 0 0.04 0
  rotation 9.94882592763367e-08 1.3064746562876517e-09 0.999999999999995 -9.03417921199438e-08
  children [
    HingeJoint {
      jointParameters HingeJointParameters {
        position 6.4582376569341234e-12
        anchor 0.06 0 0.05
      }
      device [
        RotationalMotor {
          name "Wheel 1"
        }
      ]
      endPoint Solid {
        translation 0.06 0 0.05
        rotation 3.2291069672730866e-12 -3.229118828467062e-12 1 1.5707999999999998
        children [
          DEF WHEELS Shape {
            appearance PBRAppearance {
              baseColor 0.154971 1 0.0374304
              metalness 0
            }
            geometry Cylinder {
              height 0.02
              radius 0.04
            }
          }
        ]
        name "Wheel 1"
        boundingObject USE WHEELS
        physics DEF WHEEL_PH Physics {
        }
      }
    }
    DEF CHASSIS Shape {
      appearance PBRAppearance {
        baseColor 0.986282 0.0463111 0.121553
        metalness 0
      }
      geometry Box {
        size 0.1 0.05 0.2
      }
    }
    HingeJoint {
      jointParameters HingeJointParameters {
        position 6.459079198339625e-12
        anchor 0.06 0 -0.05
      }
      device [
        RotationalMotor {
          name "Wheel 2"
        }
      ]
      endPoint Solid {
        translation 0.06 0 -0.05
        rotation 3.2295277364302634e-12 -3.2295395991698125e-12 1 1.5707999999999998
        children [
          USE WHEELS
        ]
        boundingObject USE WHEELS
        physics USE WHEEL_PH
      }
    }
    HingeJoint {
      jointParameters HingeJointParameters {
        position 6.458758482782286e-12
        anchor -0.06 0 0.05
      }
      device [
        RotationalMotor {
          name "Wheel 3"
        }
      ]
      endPoint Solid {
        translation -0.06 0 0.05
        rotation 3.22936737924062e-12 -3.2293792413911433e-12 1 1.5707999999999998
        children [
          USE WHEELS
        ]
        name "solid(1)"
        boundingObject USE WHEELS
        physics USE WHEEL_PH
      }
    }
    HingeJoint {
      jointParameters HingeJointParameters {
        position 6.459379558276126e-12
        anchor -0.06 0 -0.05
      }
      device [
        RotationalMotor {
          name "Wheel 4"
        }
      ]
      endPoint Solid {
        translation -0.06 0 -0.05
        rotation 3.229677915846873e-12 -3.2296897791380635e-12 1 1.5707999999999998
        children [
          USE WHEELS
        ]
        name "solid(2)"
        boundingObject USE WHEELS
        physics USE WHEEL_PH
      }
    }
  ]
  name "4 Wheel Robot"
  boundingObject USE CHASSIS
  physics Physics {
  }
}
